{"primaryContentSections":[{"kind":"declarations","declarations":[{"tokens":[{"kind":"keyword","text":"func"},{"kind":"text","text":" "},{"kind":"identifier","text":"resume"},{"kind":"text","text":"("},{"kind":"externalParam","text":"throwing"},{"kind":"text","text":" "},{"kind":"internalParam","text":"error"},{"kind":"text","text":": "},{"kind":"typeIdentifier","text":"Self"},{"kind":"text","text":"."},{"kind":"typeIdentifier","text":"Failure"},{"kind":"text","text":")"}],"languages":["swift"],"platforms":["macOS"]}]},{"kind":"parameters","parameters":[{"name":"error","content":[{"type":"paragraph","inlineContent":[{"type":"text","text":"The error to throw from the continuation."}]}]}]}],"schemaVersion":{"major":0,"minor":3,"patch":0},"sections":[],"variants":[{"paths":["\/documentation\/asyncobjects\/continuable\/resume(throwing:)-9qp75"],"traits":[{"interfaceLanguage":"swift"}]}],"defaultImplementationsSections":[{"title":"Continuable Implementations","identifiers":["doc:\/\/AsyncObjects\/documentation\/AsyncObjects\/Continuable\/resume(throwing:)-i9jq"]}],"identifier":{"url":"doc:\/\/AsyncObjects\/documentation\/AsyncObjects\/Continuable\/resume(throwing:)-9qp75","interfaceLanguage":"swift"},"abstract":[{"type":"text","text":"Resume the task awaiting the continuation by having it throw an error from its suspension point."}],"kind":"symbol","metadata":{"role":"symbol","title":"resume(throwing:)","roleHeading":"Instance Method","fragments":[{"kind":"keyword","text":"func"},{"kind":"text","text":" "},{"kind":"identifier","text":"resume"},{"kind":"text","text":"("},{"kind":"externalParam","text":"throwing"},{"kind":"text","text":": "},{"kind":"typeIdentifier","text":"Self"},{"kind":"text","text":"."},{"kind":"typeIdentifier","text":"Failure"},{"kind":"text","text":")"}],"symbolKind":"method","externalID":"s:12AsyncObjects11ContinuableP6resume8throwingy7FailureQz_tF","required":true,"modules":[{"name":"AsyncObjects"}]},"hierarchy":{"paths":[["doc:\/\/AsyncObjects\/documentation\/AsyncObjects","doc:\/\/AsyncObjects\/documentation\/AsyncObjects\/Continuable"]]},"references":{"doc://AsyncObjects/documentation/AsyncObjects/Continuable/resume(throwing:)-9qp75":{"defaultImplementations":1,"role":"symbol","title":"resume(throwing:)","fragments":[{"kind":"keyword","text":"func"},{"kind":"text","text":" "},{"kind":"identifier","text":"resume"},{"kind":"text","text":"("},{"kind":"externalParam","text":"throwing"},{"kind":"text","text":": "},{"kind":"typeIdentifier","text":"Self"},{"kind":"text","text":"."},{"kind":"typeIdentifier","text":"Failure"},{"kind":"text","text":")"}],"abstract":[{"type":"text","text":"Resume the task awaiting the continuation by having it throw an error from its suspension point."}],"identifier":"doc:\/\/AsyncObjects\/documentation\/AsyncObjects\/Continuable\/resume(throwing:)-9qp75","kind":"symbol","required":true,"type":"topic","url":"\/documentation\/asyncobjects\/continuable\/resume(throwing:)-9qp75"},"doc://AsyncObjects/documentation/AsyncObjects":{"role":"collection","title":"AsyncObjects","abstract":[{"type":"text","text":"Several synchronization primitives and task synchronization mechanisms introduced to aid in modern swift concurrency."}],"identifier":"doc:\/\/AsyncObjects\/documentation\/AsyncObjects","kind":"symbol","type":"topic","url":"\/documentation\/asyncobjects"},"doc://AsyncObjects/documentation/AsyncObjects/Continuable":{"role":"symbol","title":"Continuable","fragments":[{"kind":"keyword","text":"protocol"},{"kind":"text","text":" "},{"kind":"identifier","text":"Continuable"}],"abstract":[{"type":"text","text":"A type that allows to interface between synchronous and asynchronous code,"},{"type":"text","text":" "},{"type":"text","text":"by representing task state and allowing task resuming with some value or error."}],"identifier":"doc:\/\/AsyncObjects\/documentation\/AsyncObjects\/Continuable","kind":"symbol","type":"topic","navigatorTitle":[{"kind":"identifier","text":"Continuable"}],"url":"\/documentation\/asyncobjects\/continuable"},"doc://AsyncObjects/documentation/AsyncObjects/Continuable/resume(throwing:)-i9jq":{"role":"symbol","title":"resume(throwing:)","fragments":[{"kind":"keyword","text":"func"},{"kind":"text","text":" "},{"kind":"identifier","text":"resume"},{"kind":"text","text":"("},{"kind":"externalParam","text":"throwing"},{"kind":"text","text":": "},{"kind":"typeIdentifier","text":"Self"},{"kind":"text","text":"."},{"kind":"typeIdentifier","text":"Failure"},{"kind":"text","text":")"}],"abstract":[{"type":"text","text":"Resume the task awaiting the continuation by having it throw an error from its suspension point."}],"identifier":"doc:\/\/AsyncObjects\/documentation\/AsyncObjects\/Continuable\/resume(throwing:)-i9jq","kind":"symbol","type":"topic","url":"\/documentation\/asyncobjects\/continuable\/resume(throwing:)-i9jq"}}}