{"primaryContentSections":[{"kind":"declarations","declarations":[{"tokens":[{"kind":"attribute","text":"@rethrows"},{"kind":"text","text":" "},{"kind":"keyword","text":"protocol"},{"kind":"text","text":" "},{"kind":"identifier","text":"Continuable"},{"kind":"text","text":"<"},{"kind":"typeIdentifier","text":"Success"},{"kind":"text","text":", "},{"kind":"typeIdentifier","text":"Failure"},{"kind":"text","text":">"}],"languages":["swift"],"platforms":["macOS"]}]},{"kind":"content","content":[{"anchor":"overview","level":2,"type":"heading","text":"Overview"},{"type":"paragraph","inlineContent":[{"type":"text","text":"Use continuations for interfacing Swift tasks with event loops, delegate methods, callbacks,"},{"type":"text","text":" "},{"type":"text","text":"and other non-async scheduling mechanisms."}]}]}],"schemaVersion":{"major":0,"minor":3,"patch":0},"sections":[],"variants":[{"paths":["\/documentation\/asyncobjects\/continuable"],"traits":[{"interfaceLanguage":"swift"}]}],"identifier":{"url":"doc:\/\/AsyncObjects\/documentation\/AsyncObjects\/Continuable","interfaceLanguage":"swift"},"abstract":[{"type":"text","text":"A type that allows to interface between synchronous and asynchronous code,"},{"type":"text","text":" "},{"type":"text","text":"by representing task state and allowing task resuming with some value or error."}],"kind":"symbol","metadata":{"fragments":[{"kind":"keyword","text":"protocol"},{"kind":"text","text":" "},{"kind":"identifier","text":"Continuable"}],"title":"Continuable","roleHeading":"Protocol","role":"symbol","symbolKind":"protocol","externalID":"s:12AsyncObjects11ContinuableP","modules":[{"name":"AsyncObjects"}],"navigatorTitle":[{"kind":"identifier","text":"Continuable"}]},"hierarchy":{"paths":[["doc:\/\/AsyncObjects\/documentation\/AsyncObjects"]]},"topicSections":[{"title":"Associated Types","identifiers":["doc:\/\/AsyncObjects\/documentation\/AsyncObjects\/Continuable\/Failure","doc:\/\/AsyncObjects\/documentation\/AsyncObjects\/Continuable\/Success"]},{"title":"Instance Methods","identifiers":["doc:\/\/AsyncObjects\/documentation\/AsyncObjects\/Continuable\/cancel()-46gpe","doc:\/\/AsyncObjects\/documentation\/AsyncObjects\/Continuable\/cancel()-7ca4g","doc:\/\/AsyncObjects\/documentation\/AsyncObjects\/Continuable\/resume()","doc:\/\/AsyncObjects\/documentation\/AsyncObjects\/Continuable\/resume(returning:)-655td","doc:\/\/AsyncObjects\/documentation\/AsyncObjects\/Continuable\/resume(throwing:)-9qp75","doc:\/\/AsyncObjects\/documentation\/AsyncObjects\/Continuable\/resume(with:)"]}],"references":{"doc://AsyncObjects/documentation/AsyncObjects/Continuable/resume(returning:)-655td":{"defaultImplementations":1,"role":"symbol","title":"resume(returning:)","fragments":[{"kind":"keyword","text":"func"},{"kind":"text","text":" "},{"kind":"identifier","text":"resume"},{"kind":"text","text":"("},{"kind":"externalParam","text":"returning"},{"kind":"text","text":": "},{"kind":"typeIdentifier","text":"Self"},{"kind":"text","text":"."},{"kind":"typeIdentifier","text":"Success"},{"kind":"text","text":")"}],"abstract":[{"type":"text","text":"Resume the task awaiting the continuation by having it return normally from its suspension point."}],"identifier":"doc:\/\/AsyncObjects\/documentation\/AsyncObjects\/Continuable\/resume(returning:)-655td","kind":"symbol","required":true,"type":"topic","url":"\/documentation\/asyncobjects\/continuable\/resume(returning:)-655td"},"doc://AsyncObjects/documentation/AsyncObjects/Continuable/Failure":{"role":"symbol","title":"Failure","fragments":[{"kind":"keyword","text":"associatedtype"},{"kind":"text","text":" "},{"kind":"identifier","text":"Failure"},{"kind":"text","text":" : "},{"kind":"typeIdentifier","text":"Error","preciseIdentifier":"s:s5ErrorP"}],"abstract":[{"type":"text","text":"The type of error to resume the continuation with in case of failure."}],"identifier":"doc:\/\/AsyncObjects\/documentation\/AsyncObjects\/Continuable\/Failure","kind":"symbol","required":true,"type":"topic","url":"\/documentation\/asyncobjects\/continuable\/failure"},"doc://AsyncObjects/documentation/AsyncObjects/Continuable/resume()":{"role":"symbol","title":"resume()","fragments":[{"kind":"keyword","text":"func"},{"kind":"text","text":" "},{"kind":"identifier","text":"resume"},{"kind":"text","text":"()"}],"abstract":[{"type":"text","text":"Resume the task that’s awaiting the continuation by returning."}],"identifier":"doc:\/\/AsyncObjects\/documentation\/AsyncObjects\/Continuable\/resume()","kind":"symbol","type":"topic","url":"\/documentation\/asyncobjects\/continuable\/resume()"},"doc://AsyncObjects/documentation/AsyncObjects/Continuable":{"role":"symbol","title":"Continuable","fragments":[{"kind":"keyword","text":"protocol"},{"kind":"text","text":" "},{"kind":"identifier","text":"Continuable"}],"abstract":[{"type":"text","text":"A type that allows to interface between synchronous and asynchronous code,"},{"type":"text","text":" "},{"type":"text","text":"by representing task state and allowing task resuming with some value or error."}],"identifier":"doc:\/\/AsyncObjects\/documentation\/AsyncObjects\/Continuable","kind":"symbol","type":"topic","navigatorTitle":[{"kind":"identifier","text":"Continuable"}],"url":"\/documentation\/asyncobjects\/continuable"},"doc://AsyncObjects/documentation/AsyncObjects/Continuable/cancel()-7ca4g":{"role":"symbol","title":"cancel()","fragments":[{"kind":"keyword","text":"func"},{"kind":"text","text":" "},{"kind":"identifier","text":"cancel"},{"kind":"text","text":"()"}],"abstract":[{"type":"text","text":"Dummy cancellation method for continuations"},{"type":"text","text":" "},{"type":"text","text":"that don’t support cancellation."}],"identifier":"doc:\/\/AsyncObjects\/documentation\/AsyncObjects\/Continuable\/cancel()-7ca4g","kind":"symbol","type":"topic","url":"\/documentation\/asyncobjects\/continuable\/cancel()-7ca4g"},"doc://AsyncObjects/documentation/AsyncObjects/Continuable/cancel()-46gpe":{"conformance":{"constraints":[{"type":"codeVoice","code":"Failure"},{"type":"text","text":" is "},{"type":"codeVoice","code":"Error"},{"type":"text","text":"."}],"availabilityPrefix":[{"type":"text","text":"Available when"}],"conformancePrefix":[{"type":"text","text":"Conforms when"}]},"role":"symbol","title":"cancel()","fragments":[{"kind":"keyword","text":"func"},{"kind":"text","text":" "},{"kind":"identifier","text":"cancel"},{"kind":"text","text":"()"}],"abstract":[{"type":"text","text":"Cancel continuation by resuming with cancellation error."}],"identifier":"doc:\/\/AsyncObjects\/documentation\/AsyncObjects\/Continuable\/cancel()-46gpe","kind":"symbol","type":"topic","url":"\/documentation\/asyncobjects\/continuable\/cancel()-46gpe"},"doc://AsyncObjects/documentation/AsyncObjects/Continuable/Success":{"role":"symbol","title":"Success","fragments":[{"kind":"keyword","text":"associatedtype"},{"kind":"text","text":" "},{"kind":"identifier","text":"Success"}],"abstract":[{"type":"text","text":"The type of value to resume the continuation with in case of success."}],"identifier":"doc:\/\/AsyncObjects\/documentation\/AsyncObjects\/Continuable\/Success","kind":"symbol","required":true,"type":"topic","url":"\/documentation\/asyncobjects\/continuable\/success"},"doc://AsyncObjects/documentation/AsyncObjects/Continuable/resume(throwing:)-9qp75":{"defaultImplementations":1,"role":"symbol","title":"resume(throwing:)","fragments":[{"kind":"keyword","text":"func"},{"kind":"text","text":" "},{"kind":"identifier","text":"resume"},{"kind":"text","text":"("},{"kind":"externalParam","text":"throwing"},{"kind":"text","text":": "},{"kind":"typeIdentifier","text":"Self"},{"kind":"text","text":"."},{"kind":"typeIdentifier","text":"Failure"},{"kind":"text","text":")"}],"abstract":[{"type":"text","text":"Resume the task awaiting the continuation by having it throw an error from its suspension point."}],"identifier":"doc:\/\/AsyncObjects\/documentation\/AsyncObjects\/Continuable\/resume(throwing:)-9qp75","kind":"symbol","required":true,"type":"topic","url":"\/documentation\/asyncobjects\/continuable\/resume(throwing:)-9qp75"},"doc://AsyncObjects/documentation/AsyncObjects/Continuable/resume(with:)":{"role":"symbol","title":"resume(with:)","fragments":[{"kind":"keyword","text":"func"},{"kind":"text","text":" "},{"kind":"identifier","text":"resume"},{"kind":"text","text":"("},{"kind":"externalParam","text":"with"},{"kind":"text","text":": "},{"kind":"typeIdentifier","text":"Result","preciseIdentifier":"s:s6ResultO"},{"kind":"text","text":"<"},{"kind":"typeIdentifier","text":"Self"},{"kind":"text","text":"."},{"kind":"typeIdentifier","text":"Success"},{"kind":"text","text":", "},{"kind":"typeIdentifier","text":"Self"},{"kind":"text","text":"."},{"kind":"typeIdentifier","text":"Failure"},{"kind":"text","text":">)"}],"abstract":[{"type":"text","text":"Resume the task awaiting the continuation by having it either return normally"},{"type":"text","text":" "},{"type":"text","text":"or throw an error based on the state of the given "},{"type":"codeVoice","code":"Result"},{"type":"text","text":" value."}],"identifier":"doc:\/\/AsyncObjects\/documentation\/AsyncObjects\/Continuable\/resume(with:)","kind":"symbol","required":true,"type":"topic","url":"\/documentation\/asyncobjects\/continuable\/resume(with:)"},"doc://AsyncObjects/documentation/AsyncObjects":{"role":"collection","title":"AsyncObjects","abstract":[{"type":"text","text":"Several synchronization primitives and task synchronization mechanisms introduced to aid in modern swift concurrency."}],"identifier":"doc:\/\/AsyncObjects\/documentation\/AsyncObjects","kind":"symbol","type":"topic","url":"\/documentation\/asyncobjects"}}}