{"identifier":{"interfaceLanguage":"swift","url":"doc:\/\/AsyncObjects\/documentation\/AsyncObjects\/Continuable\/resume(throwing:)-9qp75"},"sections":[],"hierarchy":{"paths":[["doc:\/\/AsyncObjects\/documentation\/AsyncObjects","doc:\/\/AsyncObjects\/documentation\/AsyncObjects\/Continuable"]]},"abstract":[{"text":"Resume the task awaiting the continuation by having it throw an error from its suspension point.","type":"text"}],"variants":[{"paths":["\/documentation\/asyncobjects\/continuable\/resume(throwing:)-9qp75"],"traits":[{"interfaceLanguage":"swift"}]}],"schemaVersion":{"minor":3,"patch":0,"major":0},"metadata":{"fragments":[{"text":"func","kind":"keyword"},{"text":" ","kind":"text"},{"text":"resume","kind":"identifier"},{"text":"(","kind":"text"},{"text":"throwing","kind":"externalParam"},{"text":": ","kind":"text"},{"text":"Self","kind":"typeIdentifier"},{"text":".","kind":"text"},{"text":"Failure","kind":"typeIdentifier"},{"text":")","kind":"text"}],"modules":[{"name":"AsyncObjects"}],"externalID":"s:12AsyncObjects11ContinuableP6resume8throwingy7FailureQz_tF","roleHeading":"Instance Method","required":true,"role":"symbol","symbolKind":"method","title":"resume(throwing:)"},"primaryContentSections":[{"kind":"declarations","declarations":[{"languages":["swift"],"platforms":["Linux"],"tokens":[{"text":"func","kind":"keyword"},{"text":" ","kind":"text"},{"text":"resume","kind":"identifier"},{"text":"(","kind":"text"},{"text":"throwing","kind":"externalParam"},{"text":" ","kind":"text"},{"text":"error","kind":"internalParam"},{"text":": ","kind":"text"},{"text":"Self","kind":"typeIdentifier"},{"text":".","kind":"text"},{"text":"Failure","kind":"typeIdentifier"},{"text":")","kind":"text"}]}]},{"kind":"parameters","parameters":[{"content":[{"type":"paragraph","inlineContent":[{"type":"text","text":"The error to throw from the continuation."}]}],"name":"error"}]}],"kind":"symbol","defaultImplementationsSections":[{"identifiers":["doc:\/\/AsyncObjects\/documentation\/AsyncObjects\/Continuable\/resume(throwing:)-i9jq"],"title":"Continuable Implementations"}],"references":{"doc://AsyncObjects/documentation/AsyncObjects/Continuable/resume(throwing:)-i9jq":{"title":"resume(throwing:)","url":"\/documentation\/asyncobjects\/continuable\/resume(throwing:)-i9jq","type":"topic","fragments":[{"text":"func","kind":"keyword"},{"text":" ","kind":"text"},{"text":"resume","kind":"identifier"},{"text":"(","kind":"text"},{"text":"throwing","kind":"externalParam"},{"text":": ","kind":"text"},{"text":"Self","kind":"typeIdentifier"},{"text":".","kind":"text"},{"text":"Failure","kind":"typeIdentifier"},{"text":")","kind":"text"}],"role":"symbol","kind":"symbol","abstract":[{"text":"Resume the task awaiting the continuation by having it throw an error from its suspension point.","type":"text"}],"identifier":"doc:\/\/AsyncObjects\/documentation\/AsyncObjects\/Continuable\/resume(throwing:)-i9jq"},"doc://AsyncObjects/documentation/AsyncObjects/Continuable":{"title":"Continuable","url":"\/documentation\/asyncobjects\/continuable","type":"topic","fragments":[{"text":"protocol","kind":"keyword"},{"text":" ","kind":"text"},{"text":"Continuable","kind":"identifier"}],"role":"symbol","kind":"symbol","abstract":[{"text":"A type that allows to interface between synchronous and asynchronous code,","type":"text"},{"text":" ","type":"text"},{"text":"by representing task state and allowing task resuming with some value or error.","type":"text"}],"identifier":"doc:\/\/AsyncObjects\/documentation\/AsyncObjects\/Continuable","navigatorTitle":[{"text":"Continuable","kind":"identifier"}]},"doc://AsyncObjects/documentation/AsyncObjects":{"abstract":[{"text":"Several synchronization primitives and task synchronization mechanisms introduced to aid in modern swift concurrency.","type":"text"}],"role":"collection","title":"AsyncObjects","url":"\/documentation\/asyncobjects","identifier":"doc:\/\/AsyncObjects\/documentation\/AsyncObjects","kind":"symbol","type":"topic"},"doc://AsyncObjects/documentation/AsyncObjects/Continuable/resume(throwing:)-9qp75":{"title":"resume(throwing:)","required":true,"url":"\/documentation\/asyncobjects\/continuable\/resume(throwing:)-9qp75","type":"topic","defaultImplementations":1,"fragments":[{"text":"func","kind":"keyword"},{"text":" ","kind":"text"},{"text":"resume","kind":"identifier"},{"text":"(","kind":"text"},{"text":"throwing","kind":"externalParam"},{"text":": ","kind":"text"},{"text":"Self","kind":"typeIdentifier"},{"text":".","kind":"text"},{"text":"Failure","kind":"typeIdentifier"},{"text":")","kind":"text"}],"role":"symbol","kind":"symbol","abstract":[{"text":"Resume the task awaiting the continuation by having it throw an error from its suspension point.","type":"text"}],"identifier":"doc:\/\/AsyncObjects\/documentation\/AsyncObjects\/Continuable\/resume(throwing:)-9qp75"}}}